Workbook

Sheet RulesInfo
A1: The ADV REVIVAL Survival Guide | M1: =HYPERLINK("https://www.youtube.com/watch?v=dQw4w9WgXcQ","If an update needs to be made to the sheet, there is something incorrect, or you just want to chat, ping or DM Staff over discord! We don't mind the notifications at all!") -> If an update needs to be made to the sheet, there is something incorrect, or you just want to chat, ping or DM Staff over discord! We don't mind the notifications at all!
A2: TOURNAMENT RULES | G2: Helpful Resources:
A3: 1. Cheaters Get Banned. Forever. | G3: This right side of this info tab will give you more resources on how to play ADV to the fullest and truly get the most out of this game. We really recommend taking a look at them - As the descriptions say, they cover a variety of different topics, often just about anything you could want to know about the game.
A4: 2. Smogon Bans Carry Over.
A5: 3. Do Not Use Alts During Tour Sets.
A7: SCHEDULING FOR DUMMIES | G7: Current, ADV-Specific Resources | M7: These are resources specifically for ADV OU which are both up-to-date and useful in learning the tier. They won't give you info that may be outdated as of the time of this tournament
A8: Phase 1: Find your Pool. This is in the "Registry" tab next to your name. If you still can't see it, check your Discord roles and it should magically appear for you. | G8: =Hyperlink("https://www.smogon.com/forums/threads/adv-ou-teambuilding-strategy-archetypes-and-cores-a-data-driven-approach.3654874/","Vapicuno's Teambuilding Cores") -> Vapicuno's Teambuilding Cores | M8: An intro to some of the most common cores you'll probably see in an average game of ADV
A9: Phase 2: Find Your Opponent. If you go to your discord scheduling thread you will see your matchup The person on the other side of the bracket is your punching bag. | G9: =HYPERLINK("https://www.smogon.com/forums/threads/adv-ou-teambuilding-strategy-archetypes-and-cores-a-data-driven-approach.3654874/#post-8242663", "Vapicuno's Offense Teambuilding Guide") -> Vapicuno's Offense Teambuilding Guide | M9: An addendum to the above, which goes into more advanced detail and all sorts of teambuilding logic
A10: Phase 3: Schedule The Beatdown. This is exactly what it sounds like. You have five(5)days to play your games. Find a time within those five(5)days that works well. | G10: =HYPERLINK("https://www.smogon.com/forums/threads/adv-ou-metagame-discussion.3687814/post-9765205", "DKKoba's Mechanical Differences Sheet") -> DKKoba's Mechanical Differences Sheet | M10: A (somewhat) comprehensive list of all the mechanical differences between ADV and other generations of pokemon you may be used to
A11: Phase 4: Play The Games. Show up at the scheduled time, and make sure to be respectful to your opponent. The winner should save the replays. | G11: =HYPERLINK("https://www.smogon.com/forums/threads/adv-ou-speed-tiers.3659653/","ADV OU Speed Tiers") -> ADV OU Speed Tiers | M11: A list of how fast everything typically is, giving an idea on how much a given pokemon may invest in speed to outrun specific threats
A12: Phase 5: Send The Replays. REPLAYS ARE MANDATORY. If you do not submit a replay, do not blame the survival guide when you are coinflipped. | G12: =HYPERLINK("https://www.smogon.com/rs/articles/magic_stat_numbers", "ADV 'Magic HP' Numbers") -> ADV 'Magic HP' Numbers | M12: Some important numbers to know for teambuilding. If you're using a team that you found from another good player, this will explain the really specific EV spreads used
A13: By adhering to this simple 5-step program, you too can help support Pool Mod Sanity and prevent activity calls! If you become confused with how scheduling works, ask your Pool Mod! Your assigned Pool Mod will be next to your name in the Registry tab. | G13: =HYPERLINK("https://www.smogon.com/rs/articles/adv_threatlist","ADV OU Threatlist") -> ADV OU Threatlist | M13: An intro to all the biggest threats in ADV and what functions they typically serve on a team
G14: =HYPERLINK("https://www.smogon.com/stats/2023-08/gen3ou-1500.txt","August 2023 ADV OU Usage Stats") -> August 2023 ADV OU Usage Stats | M14: An introduction to all the stuff that's particularly popular on the ADV ladder as of August 2023 (note: If you need help making sense of the usage stats just ping/DM GraveBee)
A15: POOL MODS: Pool Mods are the people who verify your games, and they are more than happy to help with any manner of question you may have. WHEN IN DOUBT, ASK THE POOL MOD. | G15: =HYPERLINK("https://docs.google.com/spreadsheets/d/1TI_ZCan_1XHIa9YLjNzoF3Fh9awRvYJ_niBwpsIP1vE/edit#gid=491580161","ADV Beat Up Calculator") -> ADV Beat Up Calculator | M15: ADV has slightly different mechanics with the move Beat Up compared to other generations, and this calculator can help you get the exact amount you'll see in real games
G16: =HYPERLINK("https://docs.google.com/document/d/1wLcPJqQ4I5dmwvbs_GlguZ1SbLh3RcOAIRCnr18A5Ko/edit","ADV Glossary of Terms") -> ADV Glossary of Terms | M16: Do you need to know what the hell people are talking about when it comes to ADV OU? Want to find out what the hell a superachi is, or why we play basketball in a pokemon game? READ THIS.
A18: Rules of Engagement | G18: Universal, but Useful, Current Resources | M18: These resources can encompass a bit more than just ADV, but you'll probably find them useful regardless
A19: These are all the Battle-Specific rules that players are expected to adhere to when showing up to and playing their sets. Failure to adhere to them will constitute a game loss. | G19: =HYPERLINK("https://fulllifegames.com/Tools/ReplayScouter/","Replay Scouter") -> Replay Scouter | M19: This can be used to insert your opponent's replays and see what kinds of sets they used in prior matches.
A20: 1. Standard Smogon Rulesets Apply The usual clauses and ruleset of a [Gen3] OU game are to be used. | G20: =HYPERLINK("https://calc.pokemonshowdown.com/?gen=3","The Damage Calculator") -> The Damage Calculator | M20: It's pretty simple - this thing calculates damage. You can use it to determine if something really kills or is just a chance to kill. Overall, indispensible stuff.
A21: 2. We Play ADV, Not Slot Machines The following bans are in place on top of the standard Smogon ruleset due to their negative effects on a game's competitive integrity: Items: Bright Powder, King's Rock, Lax Incense, Quick Claw, Focus Band Moves: Flash, Kinesis, Sand Attack, Smokescreen, Mud-Slap, Swagger, Flatter, Confuse Ray, Supersonic, Teeter Dance, Attract Pokemon: Ninjask Failure to comply with these additional bans can lead to match loss or disqualification from the tournament. | G21: =HYPERLINK("https://chrome.google.com/webstore/detail/showdex/dabpnahpcemkfbgfbmegmncjllieilai","Showdex") -> Showdex | M21: A Chrome extension which is basically a built-in damage calculator for your Showdown instance. Don't worry, it's perfectly tournament legal.
G22: Community Samples and Team Dumps | M22: We as a community build a ton of teams, and often we build so many that we feel like sharing the secret sauce we've been cookin' up in the kitchen. This is your avenue to find that sauce
G23: =HYPERLINK("https://www.smogon.com/forums/threads/adv-ou-sample-teams-and-team-dumps.3687813/","Smogon Forum Team Dump") -> Smogon Forum Team Dump | M23: The general team dump for ADV OU teams
G24: =HYPERLINK("https://www.smogon.com/forums/threads/set-dump-team-dump-and-previously-general-metagame-discussion.3648620/","Team Dumps and Metagame Discussion Thread") -> Team Dumps and Metagame Discussion Thread | M24: Another forum thread for both team dumping and meta discussion
G25: =HYPERLINK("https://pokepast.es/fafdde1bde1b139b","McMeghan's 2022 Builder") -> McMeghan's 2022 Builder | M25: These are the various sample dumps and teams from some of the better players to touch this game (at least, the more recent dumps people have made). If you just want something you can boot up and get going, look at McMeghan's. M Dragon's and Roro's team dumps both include some analysis on top of that for those of you who enjoy reading material
G26: =HYPERLINK("https://www.smogon.com/forums/threads/set-dump-team-dump-and-previously-general-metagame-discussion.3648620/page-5#post-9400235","M Dragon's 2022 Team Dump") -> M Dragon's 2022 Team Dump
G27: =HYPERLINK("https://www.smogon.com/forums/threads/spl-xiv-teams-reflections-report.3720792/","Roro's SPL Team Dump") -> Roro's SPL Team Dump
G28: =HYPERLINK("https://youtu.be/BkvCZ18ySWE?si=8HZ8n2UhAwv6N3ng","ADV Offense for Beginners") -> ADV Offense for Beginners | M28: Jim Cool explains ADV Offense and teambuilding using some of the most classic, well-used teams in the meta, as well as why you're doing what you're doing beyond just giving teams.
G29: =HYPERLINK("https://www.smogon.com/forums/threads/adv-ou-creative-sets-synergistic-cores-and-concepts.3687815/","ADV Creative Sets Thread") -> ADV Creative Sets Thread | M29: This is the playground where various cool sets can be posted by the community for when you really want to shake things up
G30: Forums for Other Resources/Replays | M30: Want to find tons of chatter about all manner of competitive mons, ADV included? Check out the forums!
G31: =HYPERLINK("https://www.smogon.com/forums/forums/adv/","Ruins of Alph ADV Forums") -> Ruins of Alph ADV Forums | M31: RoA is Smogon's go-to source for anything from gen1 to gen8, including ADV
G32: =HYPERLINK("https://www.pokemonperfect.com/forums/index.php?forums/adv-ou.73/","Pokemon Perfect ADV Forums") -> Pokemon Perfect ADV Forums | M32: An alternative forum to Smogon, Pokemon Perfect is another great place to talk about competitive mons, especially the old gens
G33: =HYPERLINK("https://www.smogon.com/forums/forums/old-gen-metagames-circuits.475/?prefix_id=419","Smogon ADV Tournaments") -> Smogon ADV Tournaments | M33: This is the dedicated place for RoA to post what's going on as far as other ADV tours going on
G34: ADV Community Youtube Channels | M34: If you feel like injecting ADV content into your brain automatically, or just want to support a wider variety of the ADV community, check these out
G35: =HYPERLINK("https://www.youtube.com/@revivaltournaments","Revival Tournaments") -> Revival Tournaments | M35: All the gameplay from this server and more!
G36: =HYPERLINK("https://www.youtube.com/@jimothycool","Jimothy Cool") -> Jimothy Cool | M36: Probably why you are here. Good talk about a variety of formats but has some particularly great videos in terms of the smaller ADV niches which make this meta so deep
G37: =HYPERLINK("https://youtube.com/@vapicuno?feature=shared","Vapicuno") -> Vapicuno | M37: One of the more data-inclined folks in the community, Vapicuno has a bunch of videos of getting to higher points on the ladder with some things you may not expect
G38: =HYPERLINK("https://www.youtube.com/@BKCplaysPokemon","BKC") -> BKC | M38: BKC's channel is a great source of more long-form content that covers a variety of formats. Great place to look for why things make a meta function the way they do
G39: =HYPERLINK("https://www.youtube.com/@thelinearcurveadvanalysis9183","thelinearcurve") -> thelinearcurve | M39: Arguably the best ADVer to ever ADV.
G40: =HYPERLINK("https://www.youtube.com/@CALLOUSNarrates","CALLOUS") -> CALLOUS | M40: An ADV commentator who's hosted the biggest ADV tour of the year for several years, good place to go if you're really into high-level replay analysis / commentary
G41: =HYPERLINK("https://m.youtube.com/channel/UCdYIv_VZo5kZ84_urxznX2Q","Zpanther19") -> Zpanther19 | M41: A newer addition to the ADV scene, Zpanther focuses on both ADV OU and Draft League. Pretty great at explaining things in a way that is practical and simple
G42: =HYPERLINK("https://www.youtube.com/@lrxc3403","LRXC") -> LRXC | M42: Great source of general ADV/Gen3 content, and current 2nd place all time record for Emerald's Battle Factory
...

Sheet Swiss Registry
A1: Seed | B1: Player Name | C1: Record | D1: R1 | E1: R2 | F1: R3 | G1: R4 | H1: R5 | I1: R6 | J1: R7 | K1: R8 | L1: R9 | M1: R10 | N1: ID
A2: 1 | B2: Fakes | C2: =CONCATENATE(COUNTIF(D2:M2,"W") , " - " , COUNTIF(D2:M2, "L")) -> 7 - 2 | D2: =iferror(if(LEFT(VLOOKUP($B2,'Round 1'!$B$2:$H$361,7,false),1)="A","W",if(LEFT(VLOOKUP($B2,'Round 1'!$B$2:$H$361,7,false),1)="B","L","")),if(LEFT(VLOOKUP($B2,'Round 1'!$F$2:$H$361,3,false),1)="b","W",if(LEFT(VLOOKUP($B2,'Round 1'!$F$2:$H$361,3,false),1)="a","L",""))) -> W | E2: =iferror(if(LEFT(VLOOKUP($B2,'Round 2'!$C$2:$J$361,8,false),1)="A","W",if(LEFT(VLOOKUP($B2,'Round 2'!$C$2:$J$361,8,false),1)="B","L","")),if(LEFT(VLOOKUP($B2,'Round 2'!$G$2:$J$361,4,false),1)="b","W",if(LEFT(VLOOKUP($B2,'Round 2'!$G$2:$J$361,4,false),1)="a","L",""))) -> W | F2: =iferror(if(LEFT(VLOOKUP($B2,'Round 3'!$B$2:$H$361,7,false),1)="A","W",if(LEFT(VLOOKUP($B2,'Round 3'!$B$2:$H$361,7,false),1)="B","L","")),if(LEFT(VLOOKUP($B2,'Round 3'!$F$2:$H$361,3,false),1)="b","W",if(LEFT(VLOOKUP($B2,'Round 3'!$F$2:$H$361,3,false),1)="a","L",""))) -> W | G2: =iferror(if(LEFT(VLOOKUP($B2,'Round 4'!$B$2:$H$361,7,false),1)="A","W",if(LEFT(VLOOKUP($B2,'Round 4'!$B$2:$H$361,7,false),1)="B","L","")),if(LEFT(VLOOKUP($B2,'Round 4'!$F$2:$H$361,3,false),1)="b","W",if(LEFT(VLOOKUP($B2,'Round 4'!$F$2:$H$361,3,false),1)="a","L",""))) -> W | H2: =iferror(if(LEFT(VLOOKUP($B2,'Round 5'!$B$2:$H$361,7,false),1)="A","W",if(LEFT(VLOOKUP($B2,'Round 5'!$B$2:$H$361,7,false),1)="B","L","")),if(LEFT(VLOOKUP($B2,'Round 5'!$F$2:$H$361,3,false),1)="b","W",if(LEFT(VLOOKUP($B2,'Round 5'!$F$2:$H$361,3,false),1)="a","L",""))) -> W | I2: =iferror(if(LEFT(VLOOKUP($B2,'Round 6'!$B$2:$H$361,7,false),1)="A","W",if(LEFT(VLOOKUP($B2,'Round 6'!$B$2:$H$361,7,false),1)="B","L","")),if(LEFT(VLOOKUP($B2,'Round 6'!$F$2:$H$361,3,false),1)="b","W",if(LEFT(VLOOKUP($B2,'Round 6'!$F$2:$H$361,3,false),1)="a","L",""))) -> W | J2: =iferror(iferror(if(LEFT(VLOOKUP($B2,'Round 7'!$B$2:$H$361,7,false),1)="A","W",if(LEFT(VLOOKUP($B2,'Round 7'!$B$2:$H$361,7,false),1)="B","L","")),if(LEFT(VLOOKUP($B2,'Round 7'!$F$2:$H$361,3,false),1)="b","W",if(LEFT(VLOOKUP($B2,'Round 7'!$F$2:$H$361,3,false),1)="a","L",""))),"") -> W | K2: =iferror(iferror(if(LEFT(VLOOKUP($B2,'Round 8'!$B$2:$H$361,7,false),1)="A","W",if(LEFT(VLOOKUP($B2,'Round 8'!$B$2:$H$361,7,false),1)="B","L","")),if(LEFT(VLOOKUP($B2,'Round 8'!$F$2:$H$361,3,false),1)="b","W",if(LEFT(VLOOKUP($B2,'Round 8'!$F$2:$H$361,3,false),1)="a","L",""))),"") -> L | L2: =iferror(iferror(if(LEFT(VLOOKUP($B2,'Round 9'!$B$2:$H$361,7,false),1)="A","W",if(LEFT(VLOOKUP($B2,'Round 9'!$B$2:$H$361,7,false),1)="B","L","")),if(LEFT(VLOOKUP($B2,'Round 9'!$F$2:$H$361,3,false),1)="b","W",if(LEFT(VLOOKUP($B2,'Round 9'!$F$2:$H$361,3,false),1)="a","L",""))),"") -> L | M2: =iferror(iferror(if(LEFT(VLOOKUP($B2,'Round 10'!$B$2:$H$362,7,false),1)="A","W",if(LEFT(VLOOKUP($B2,'Round 10'!$B$2:$H$362,7,false),1)="B","L","")),if(LEFT(VLOOKUP($B2,'Round 10'!$F$2:$H$362,3,false),1)="b","W",if(LEFT(VLOOKUP($B2,'Round 10'!$F$2:$H$362,3,false),1)="a","L",""))),"") | N2: 917864414269550693
A3: 2 | B3: Altina | C3: =CONCATENATE(COUNTIF(D3:M3,"W") , " - " , COUNTIF(D3:M3, "L")) -> 2 - 3 | D3: =iferror(if(LEFT(VLOOKUP($B3,'Round 1'!$B$2:$H$361,7,false),1)="A","W",if(LEFT(VLOOKUP($B3,'Round 1'!$B$2:$H$361,7,false),1)="B","L","")),if(LEFT(VLOOKUP($B3,'Round 1'!$F$2:$H$361,3,false),1)="b","W",if(LEFT(VLOOKUP($B3,'Round 1'!$F$2:$H$361,3,false),1)="a","L",""))) -> L | E3: =iferror(if(LEFT(VLOOKUP($B3,'Round 2'!$C$2:$J$361,8,false),1)="A","W",if(LEFT(VLOOKUP($B3,'Round 2'!$C$2:$J$361,8,false),1)="B","L","")),if(LEFT(VLOOKUP($B3,'Round 2'!$G$2:$J$361,4,false),1)="b","W",if(LEFT(VLOOKUP($B3,'Round 2'!$G$2:$J$361,4,false),1)="a","L",""))) -> L | F3: =iferror(if(LEFT(VLOOKUP($B3,'Round 3'!$B$2:$H$361,7,false),1)="A","W",if(LEFT(VLOOKUP($B3,'Round 3'!$B$2:$H$361,7,false),1)="B","L","")),if(LEFT(VLOOKUP($B3,'Round 3'!$F$2:$H$361,3,false),1)="b","W",if(LEFT(VLOOKUP($B3,'Round 3'!$F$2:$H$361,3,false),1)="a","L",""))) -> W | G3: =iferror(if(LEFT(VLOOKUP($B3,'Round 4'!$B$2:$H$361,7,false),1)="A","W",if(LEFT(VLOOKUP($B3,'Round 4'!$B$2:$H$361,7,false),1)="B","L","")),if(LEFT(VLOOKUP($B3,'Round 4'!$F$2:$H$361,3,false),1)="b","W",if(LEFT(VLOOKUP($B3,'Round 4'!$F$2:$H$361,3,false),1)="a","L",""))) -> W | H3: =iferror(if(LEFT(VLOOKUP($B3,'Round 5'!$B$2:$H$361,7,false),1)="A","W",if(LEFT(VLOOKUP($B3,'Round 5'!$B$2:$H$361,7,false),1)="B","L","")),if(LEFT(VLOOKUP($B3,'Round 5'!$F$2:$H$361,3,false),1)="b","W",if(LEFT(VLOOKUP($B3,'Round 5'!$F$2:$H$361,3,false),1)="a","L",""))) -> L | J3: =iferror(iferror(if(LEFT(VLOOKUP($B3,'Round 7'!$B$2:$H$361,7,false),1)="A","W",if(LEFT(VLOOKUP($B3,'Round 7'!$B$2:$H$361,7,false),1)="B","L","")),if(LEFT(VLOOKUP($B3,'Round 7'!$F$2:$H$361,3,false),1)="b","W",if(LEFT(VLOOKUP($B3,'Round 7'!$F$2:$H$361,3,false),1)="a","L",""))),"") | K3: =iferror(iferror(if(LEFT(VLOOKUP($B3,'Round 8'!$B$2:$H$361,7,false),1)="A","W",if(LEFT(VLOOKUP($B3,'Round 8'!$B$2:$H$361,7,false),1)="B","L","")),if(LEFT(VLOOKUP($B3,'Round 8'!$F$2:$H$361,3,false),1)="b","W",if(LEFT(VLOOKUP($B3,'Round 8'!$F$2:$H$361,3,false),1)="a","L",""))),"") | L3: =iferror(iferror(if(LEFT(VLOOKUP($B3,'Round 9'!$B$2:$H$361,7,false),1)="A","W",if(LEFT(VLOOKUP($B3,'Round 9'!$B$2:$H$361,7,false),1)="B","L","")),if(LEFT(VLOOKUP($B3,'Round 9'!$F$2:$H$361,3,false),1)="b","W",if(LEFT(VLOOKUP($B3,'Round 9'!$F$2:$H$361,3,false),1)="a","L",""))),"") | M3: =iferror(iferror(if(LEFT(VLOOKUP($B3,'Round 10'!$B$2:$H$362,7,false),1)="A","W",if(LEFT(VLOOKUP($B3,'Round 10'!$B$2:$H$362,7,false),1)="B","L","")),if(LEFT(VLOOKUP($B3,'Round 10'!$F$2:$H$362,3,false),1)="b","W",if(LEFT(VLOOKUP($B3,'Round 10'!$F$2:$H$362,3,false),1)="a","L",""))),"") | N3: 195417421459226626
A4: 3 | B4: Triangles | C4: =CONCATENATE(COUNTIF(D4:M4,"W") , " - " , COUNTIF(D4:M4, "L")) -> 8 - 1 | D4: =iferror(if(LEFT(VLOOKUP($B4,'Round 1'!$B$2:$H$361,7,false),1)="A","W",if(LEFT(VLOOKUP($B4,'Round 1'!$B$2:$H$361,7,false),1)="B","L","")),if(LEFT(VLOOKUP($B4,'Round 1'!$F$2:$H$361,3,false),1)="b","W",if(LEFT(VLOOKUP($B4,'Round 1'!$F$2:$H$361,3,false),1)="a","L",""))) -> W | E4: =iferror(if(LEFT(VLOOKUP($B4,'Round 2'!$C$2:$J$361,8,false),1)="A","W",if(LEFT(VLOOKUP($B4,'Round 2'!$C$2:$J$361,8,false),1)="B","L","")),if(LEFT(VLOOKUP($B4,'Round 2'!$G$2:$J$361,4,false),1)="b","W",if(LEFT(VLOOKUP($B4,'Round 2'!$G$2:$J$361,4,false),1)="a","L",""))) -> W | F4: =iferror(if(LEFT(VLOOKUP($B4,'Round 3'!$B$2:$H$361,7,false),1)="A","W",if(LEFT(VLOOKUP($B4,'Round 3'!$B$2:$H$361,7,false),1)="B","L","")),if(LEFT(VLOOKUP($B4,'Round 3'!$F$2:$H$361,3,false),1)="b","W",if(LEFT(VLOOKUP($B4,'Round 3'!$F$2:$H$361,3,false),1)="a","L",""))) -> W | G4: =iferror(if(LEFT(VLOOKUP($B4,'Round 4'!$B$2:$H$361,7,false),1)="A","W",if(LEFT(VLOOKUP($B4,'Round 4'!$B$2:$H$361,7,false),1)="B","L","")),if(LEFT(VLOOKUP($B4,'Round 4'!$F$2:$H$361,3,false),1)="b","W",if(LEFT(VLOOKUP($B4,'Round 4'!$F$2:$H$361,3,false),1)="a","L",""))) -> W | H4: =iferror(if(LEFT(VLOOKUP($B4,'Round 5'!$B$2:$H$361,7,false),1)="A","W",if(LEFT(VLOOKUP($B4,'Round 5'!$B$2:$H$361,7,false),1)="B","L","")),if(LEFT(VLOOKUP($B4,'Round 5'!$F$2:$H$361,3,false),1)="b","W",if(LEFT(VLOOKUP($B4,'Round 5'!$F$2:$H$361,3,false),1)="a","L",""))) -> L | I4: =iferror(if(LEFT(VLOOKUP($B4,'Round 6'!$B$2:$H$361,7,false),1)="A","W",if(LEFT(VLOOKUP($B4,'Round 6'!$B$2:$H$361,7,false),1)="B","L","")),if(LEFT(VLOOKUP($B4,'Round 6'!$F$2:$H$361,3,false),1)="b","W",if(LEFT(VLOOKUP($B4,'Round 6'!$F$2:$H$361,3,false),1)="a","L",""))) -> W | J4: =iferror(iferror(if(LEFT(VLOOKUP($B4,'Round 7'!$B$2:$H$361,7,false),1)="A","W",if(LEFT(VLOOKUP($B4,'Round 7'!$B$2:$H$361,7,false),1)="B","L","")),if(LEFT(VLOOKUP($B4,'Round 7'!$F$2:$H$361,3,false),1)="b","W",if(LEFT(VLOOKUP($B4,'Round 7'!$F$2:$H$361,3,false),1)="a","L",""))),"") -> W | K4: =iferror(iferror(if(LEFT(VLOOKUP($B4,'Round 8'!$B$2:$H$361,7,false),1)="A","W",if(LEFT(VLOOKUP($B4,'Round 8'!$B$2:$H$361,7,false),1)="B","L","")),if(LEFT(VLOOKUP($B4,'Round 8'!$F$2:$H$361,3,false),1)="b","W",if(LEFT(VLOOKUP($B4,'Round 8'!$F$2:$H$361,3,false),1)="a","L",""))),"") -> W | L4: =iferror(iferror(if(LEFT(VLOOKUP($B4,'Round 9'!$B$2:$H$361,7,false),1)="A","W",if(LEFT(VLOOKUP($B4,'Round 9'!$B$2:$H$361,7,false),1)="B","L","")),if(LEFT(VLOOKUP($B4,'Round 9'!$F$2:$H$361,3,false),1)="b","W",if(LEFT(VLOOKUP($B4,'Round 9'!$F$2:$H$361,3,false),1)="a","L",""))),"") -> W | M4: =iferror(iferror(if(LEFT(VLOOKUP($B4,'Round 10'!$B$2:$H$362,7,false),1)="A","W",if(LEFT(VLOOKUP($B4,'Round 10'!$B$2:$H$362,7,false),1)="B","L","")),if(LEFT(VLOOKUP($B4,'Round 10'!$F$2:$H$362,3,false),1)="b","W",if(LEFT(VLOOKUP($B4,'Round 10'!$F$2:$H$362,3,false),1)="a","L",""))),"") | N4: 587394354725912717
A5: 4 | B5: pkLeech | C5: =CONCATENATE(COUNTIF(D5:M5,"W") , " - " , COUNTIF(D5:M5, "L")) -> 7 - 2 | D5: =iferror(if(LEFT(VLOOKUP($B5,'Round 1'!$B$2:$H$361,7,false),1)="A","W",if(LEFT(VLOOKUP($B5,'Round 1'!$B$2:$H$361,7,false),1)="B","L","")),if(LEFT(VLOOKUP($B5,'Round 1'!$F$2:$H$361,3,false),1)="b","W",if(LEFT(VLOOKUP($B5,'Round 1'!$F$2:$H$361,3,false),1)="a","L",""))) -> W | E5: =iferror(if(LEFT(VLOOKUP($B5,'Round 2'!$C$2:$J$361,8,false),1)="A","W",if(LEFT(VLOOKUP($B5,'Round 2'!$C$2:$J$361,8,false),1)="B","L","")),if(LEFT(VLOOKUP($B5,'Round 2'!$G$2:$J$361,4,false),1)="b","W",if(LEFT(VLOOKUP($B5,'Round 2'!$G$2:$J$361,4,false),1)="a","L",""))) -> W | F5: =iferror(if(LEFT(VLOOKUP($B5,'Round 3'!$B$2:$H$361,7,false),1)="A","W",if(LEFT(VLOOKUP($B5,'Round 3'!$B$2:$H$361,7,false),1)="B","L","")),if(LEFT(VLOOKUP($B5,'Round 3'!$F$2:$H$361,3,false),1)="b","W",if(LEFT(VLOOKUP($B5,'Round 3'!$F$2:$H$361,3,false),1)="a","L",""))) -> L | G5: =iferror(if(LEFT(VLOOKUP($B5,'Round 4'!$B$2:$H$361,7,false),1)="A","W",if(LEFT(VLOOKUP($B5,'Round 4'!$B$2:$H$361,7,false),1)="B","L","")),if(LEFT(VLOOKUP($B5,'Round 4'!$F$2:$H$361,3,false),1)="b","W",if(LEFT(VLOOKUP($B5,'Round 4'!$F$2:$H$361,3,false),1)="a","L",""))) -> W | H5: =iferror(if(LEFT(VLOOKUP($B5,'Round 5'!$B$2:$H$361,7,false),1)="A","W",if(LEFT(VLOOKUP($B5,'Round 5'!$B$2:$H$361,7,false),1)="B","L","")),if(LEFT(VLOOKUP($B5,'Round 5'!$F$2:$H$361,3,false),1)="b","W",if(LEFT(VLOOKUP($B5,'Round 5'!$F$2:$H$361,3,false),1)="a","L",""))) -> W | I5: =iferror(if(LEFT(VLOOKUP($B5,'Round 6'!$B$2:$H$361,7,false),1)="A","W",if(LEFT(VLOOKUP($B5,'Round 6'!$B$2:$H$361,7,false),1)="B","L","")),if(LEFT(VLOOKUP($B5,'Round 6'!$F$2:$H$361,3,false),1)="b","W",if(LEFT(VLOOKUP($B5,'Round 6'!$F$2:$H$361,3,false),1)="a","L",""))) -> W | J5: =iferror(iferror(if(LEFT(VLOOKUP($B5,'Round 7'!$B$2:$H$361,7,false),1)="A","W",if(LEFT(VLOOKUP($B5,'Round 7'!$B$2:$H$361,7,false),1)="B","L","")),if(LEFT(VLOOKUP($B5,'Round 7'!$F$2:$H$361,3,false),1)="b","W",if(LEFT(VLOOKUP($B5,'Round 7'!$F$2:$H$361,3,false),1)="a","L",""))),"") -> W | K5: =iferror(iferror(if(LEFT(VLOOKUP($B5,'Round 8'!$B$2:$H$361,7,false),1)="A","W",if(LEFT(VLOOKUP($B5,'Round 8'!$B$2:$H$361,7,false),1)="B","L","")),if(LEFT(VLOOKUP($B5,'Round 8'!$F$2:$H$361,3,false),1)="b","W",if(LEFT(VLOOKUP($B5,'Round 8'!$F$2:$H$361,3,false),1)="a","L",""))),"") -> W | L5: =iferror(iferror(if(LEFT(VLOOKUP($B5,'Round 9'!$B$2:$H$361,7,false),1)="A","W",if(LEFT(VLOOKUP($B5,'Round 9'!$B$2:$H$361,7,false),1)="B","L","")),if(LEFT(VLOOKUP($B5,'Round 9'!$F$2:$H$361,3,false),1)="b","W",if(LEFT(VLOOKUP($B5,'Round 9'!$F$2:$H$361,3,false),1)="a","L",""))),"") -> L | M5: =iferror(iferror(if(LEFT(VLOOKUP($B5,'Round 10'!$B$2:$H$362,7,false),1)="A","W",if(LEFT(VLOOKUP($B5,'Round 10'!$B$2:$H$362,7,false),1)="B","L","")),if(LEFT(VLOOKUP($B5,'Round 10'!$F$2:$H$362,3,false),1)="b","W",if(LEFT(VLOOKUP($B5,'Round 10'!$F$2:$H$362,3,false),1)="a","L",""))),"") | N5: 461288985944391708
A6: 5 | B6: Caloom | C6: =CONCATENATE(COUNTIF(D6:M6,"W") , " - " , COUNTIF(D6:M6, "L")) -> 7 - 2 | D6: =iferror(if(LEFT(VLOOKUP($B6,'Round 1'!$B$2:$H$361,7,false),1)="A","W",if(LEFT(VLOOKUP($B6,'Round 1'!$B$2:$H$361,7,false),1)="B","L","")),if(LEFT(VLOOKUP($B6,'Round 1'!$F$2:$H$361,3,false),1)="b","W",if(LEFT(VLOOKUP($B6,'Round 1'!$F$2:$H$361,3,false),1)="a","L",""))) -> L | E6: =iferror(if(LEFT(VLOOKUP($B6,'Round 2'!$C$2:$J$361,8,false),1)="A","W",if(LEFT(VLOOKUP($B6,'Round 2'!$C$2:$J$361,8,false),1)="B","L","")),if(LEFT(VLOOKUP($B6,'Round 2'!$G$2:$J$361,4,false),1)="b","W",if(LEFT(VLOOKUP($B6,'Round 2'!$G$2:$J$361,4,false),1)="a","L",""))) -> W | F6: =iferror(if(LEFT(VLOOKUP($B6,'Round 3'!$B$2:$H$361,7,false),1)="A","W",if(LEFT(VLOOKUP($B6,'Round 3'!$B$2:$H$361,7,false),1)="B","L","")),if(LEFT(VLOOKUP($B6,'Round 3'!$F$2:$H$361,3,false),1)="b","W",if(LEFT(VLOOKUP($B6,'Round 3'!$F$2:$H$361,3,false),1)="a","L",""))) -> W | G6: =iferror(if(LEFT(VLOOKUP($B6,'Round 4'!$B$2:$H$361,7,false),1)="A","W",if(LEFT(VLOOKUP($B6,'Round 4'!$B$2:$H$361,7,false),1)="B","L","")),if(LEFT(VLOOKUP($B6,'Round 4'!$F$2:$H$361,3,false),1)="b","W",if(LEFT(VLOOKUP($B6,'Round 4'!$F$2:$H$361,3,false),1)="a","L",""))) -> W | H6: =iferror(if(LEFT(VLOOKUP($B6,'Round 5'!$B$2:$H$361,7,false),1)="A","W",if(LEFT(VLOOKUP($B6,'Round 5'!$B$2:$H$361,7,false),1)="B","L","")),if(LEFT(VLOOKUP($B6,'Round 5'!$F$2:$H$361,3,false),1)="b","W",if(LEFT(VLOOKUP($B6,'Round 5'!$F$2:$H$361,3,false),1)="a","L",""))) -> L | I6: =iferror(if(LEFT(VLOOKUP($B6,'Round 6'!$B$2:$H$361,7,false),1)="A","W",if(LEFT(VLOOKUP($B6,'Round 6'!$B$2:$H$361,7,false),1)="B","L","")),if(LEFT(VLOOKUP($B6,'Round 6'!$F$2:$H$361,3,false),1)="b","W",if(LEFT(VLOOKUP($B6,'Round 6'!$F$2:$H$361,3,false),1)="a","L",""))) -> W | J6: =iferror(iferror(if(LEFT(VLOOKUP($B6,'Round 7'!$B$2:$H$361,7,false),1)="A","W",if(LEFT(VLOOKUP($B6,'Round 7'!$B$2:$H$361,7,false),1)="B","L","")),if(LEFT(VLOOKUP($B6,'Round 7'!$F$2:$H$361,3,false),1)="b","W",if(LEFT(VLOOKUP($B6,'Round 7'!$F$2:$H$361,3,false),1)="a","L",""))),"") -> W | K6: =iferror(iferror(if(LEFT(VLOOKUP($B6,'Round 8'!$B$2:$H$361,7,false),1)="A","W",if(LEFT(VLOOKUP($B6,'Round 8'!$B$2:$H$361,7,false),1)="B","L","")),if(LEFT(VLOOKUP($B6,'Round 8'!$F$2:$H$361,3,false),1)="b","W",if(LEFT(VLOOKUP($B6,'Round 8'!$F$2:$H$361,3,false),1)="a","L",""))),"") -> W | L6: =iferror(iferror(if(LEFT(VLOOKUP($B6,'Round 9'!$B$2:$H$361,7,false),1)="A","W",if(LEFT(VLOOKUP($B6,'Round 9'!$B$2:$H$361,7,false),1)="B","L","")),if(LEFT(VLOOKUP($B6,'Round 9'!$F$2:$H$361,3,false),1)="b","W",if(LEFT(VLOOKUP($B6,'Round 9'!$F$2:$H$361,3,false),1)="a","L",""))),"") -> W | M6: =iferror(iferror(if(LEFT(VLOOKUP($B6,'Round 10'!$B$2:$H$362,7,false),1)="A","W",if(LEFT(VLOOKUP($B6,'Round 10'!$B$2:$H$362,7,false),1)="B","L","")),if(LEFT(VLOOKUP($B6,'Round 10'!$F$2:$H$362,3,false),1)="b","W",if(LEFT(VLOOKUP($B6,'Round 10'!$F$2:$H$362,3,false),1)="a","L",""))),"") | N6: 428981810811109386
A7: 6 | B7: Fear | C7: =CONCATENATE(COUNTIF(D7:M7,"W") , " - " , COUNTIF(D7:M7, "L")) -> 8 - 1 | D7: =iferror(if(LEFT(VLOOKUP($B7,'Round 1'!$B$2:$H$361,7,false),1)="A","W",if(LEFT(VLOOKUP($B7,'Round 1'!$B$2:$H$361,7,false),1)="B","L","")),if(LEFT(VLOOKUP($B7,'Round 1'!$F$2:$H$361,3,false),1)="b","W",if(LEFT(VLOOKUP($B7,'Round 1'!$F$2:$H$361,3,false),1)="a","L",""))) -> W | E7: =iferror(if(LEFT(VLOOKUP($B7,'Round 2'!$C$2:$J$361,8,false),1)="A","W",if(LEFT(VLOOKUP($B7,'Round 2'!$C$2:$J$361,8,false),1)="B","L","")),if(LEFT(VLOOKUP($B7,'Round 2'!$G$2:$J$361,4,false),1)="b","W",if(LEFT(VLOOKUP($B7,'Round 2'!$G$2:$J$361,4,false),1)="a","L",""))) -> W | F7: =iferror(if(LEFT(VLOOKUP($B7,'Round 3'!$B$2:$H$361,7,false),1)="A","W",if(LEFT(VLOOKUP($B7,'Round 3'!$B$2:$H$361,7,false),1)="B","L","")),if(LEFT(VLOOKUP($B7,'Round 3'!$F$2:$H$361,3,false),1)="b","W",if(LEFT(VLOOKUP($B7,'Round 3'!$F$2:$H$361,3,false),1)="a","L",""))) -> W | G7: =iferror(if(LEFT(VLOOKUP($B7,'Round 4'!$B$2:$H$361,7,false),1)="A","W",if(LEFT(VLOOKUP($B7,'Round 4'!$B$2:$H$361,7,false),1)="B","L","")),if(LEFT(VLOOKUP($B7,'Round 4'!$F$2:$H$361,3,false),1)="b","W",if(LEFT(VLOOKUP($B7,'Round 4'!$F$2:$H$361,3,false),1)="a","L",""))) -> W | H7: =iferror(if(LEFT(VLOOKUP($B7,'Round 5'!$B$2:$H$361,7,false),1)="A","W",if(LEFT(VLOOKUP($B7,'Round 5'!$B$2:$H$361,7,false),1)="B","L","")),if(LEFT(VLOOKUP($B7,'Round 5'!$F$2:$H$361,3,false),1)="b","W",if(LEFT(VLOOKUP($B7,'Round 5'!$F$2:$H$361,3,false),1)="a","L",""))) -> W | I7: =iferror(if(LEFT(VLOOKUP($B7,'Round 6'!$B$2:$H$361,7,false),1)="A","W",if(LEFT(VLOOKUP($B7,'Round 6'!$B$2:$H$361,7,false),1)="B","L","")),if(LEFT(VLOOKUP($B7,'Round 6'!$F$2:$H$361,3,false),1)="b","W",if(LEFT(VLOOKUP($B7,'Round 6'!$F$2:$H$361,3,false),1)="a","L",""))) -> W | J7: =iferror(iferror(if(LEFT(VLOOKUP($B7,'Round 7'!$B$2:$H$361,7,false),1)="A","W",if(LEFT(VLOOKUP($B7,'Round 7'!$B$2:$H$361,7,false),1)="B","L","")),if(LEFT(VLOOKUP($B7,'Round 7'!$F$2:$H$361,3,false),1)="b","W",if(LEFT(VLOOKUP($B7,'Round 7'!$F$2:$H$361,3,false),1)="a","L",""))),"") -> L | K7: =iferror(iferror(if(LEFT(VLOOKUP($B7,'Round 8'!$B$2:$H$361,7,false),1)="A","W",if(LEFT(VLOOKUP($B7,'Round 8'!$B$2:$H$361,7,false),1)="B","L","")),if(LEFT(VLOOKUP($B7,'Round 8'!$F$2:$H$361,3,false),1)="b","W",if(LEFT(VLOOKUP($B7,'Round 8'!$F$2:$H$361,3,false),1)="a","L",""))),"") -> W | L7: =iferror(iferror(if(LEFT(VLOOKUP($B7,'Round 9'!$B$2:$H$361,7,false),1)="A","W",if(LEFT(VLOOKUP($B7,'Round 9'!$B$2:$H$361,7,false),1)="B","L","")),if(LEFT(VLOOKUP($B7,'Round 9'!$F$2:$H$361,3,false),1)="b","W",if(LEFT(VLOOKUP($B7,'Round 9'!$F$2:$H$361,3,false),1)="a","L",""))),"") -> W | M7: =iferror(iferror(if(LEFT(VLOOKUP($B7,'Round 10'!$B$2:$H$362,7,false),1)="A","W",if(LEFT(VLOOKUP($B7,'Round 10'!$B$2:$H$362,7,false),1)="B","L","")),if(LEFT(VLOOKUP($B7,'Round 10'!$F$2:$H$362,3,false),1)="b","W",if(LEFT(VLOOKUP($B7,'Round 10'!$F$2:$H$362,3,false),1)="a","L",""))),"") | N7: 125981893828149248
A8: 7 | B8: jumpy23 | C8: =CONCATENATE(COUNTIF(D8:M8,"W") , " - " , COUNTIF(D8:M8, "L")) -> 10 - 0 | D8: =iferror(if(LEFT(VLOOKUP($B8,'Round 1'!$B$2:$H$361,7,false),1)="A","W",if(LEFT(VLOOKUP($B8,'Round 1'!$B$2:$H$361,7,false),1)="B","L","")),if(LEFT(VLOOKUP($B8,'Round 1'!$F$2:$H$361,3,false),1)="b","W",if(LEFT(VLOOKUP($B8,'Round 1'!$F$2:$H$361,3,false),1)="a","L",""))) -> W | E8: =iferror(if(LEFT(VLOOKUP($B8,'Round 2'!$C$2:$J$361,8,false),1)="A","W",if(LEFT(VLOOKUP($B8,'Round 2'!$C$2:$J$361,8,false),1)="B","L","")),if(LEFT(VLOOKUP($B8,'Round 2'!$G$2:$J$361,4,false),1)="b","W",if(LEFT(VLOOKUP($B8,'Round 2'!$G$2:$J$361,4,false),1)="a","L",""))) -> W | F8: =iferror(if(LEFT(VLOOKUP($B8,'Round 3'!$B$2:$H$361,7,false),1)="A","W",if(LEFT(VLOOKUP($B8,'Round 3'!$B$2:$H$361,7,false),1)="B","L","")),if(LEFT(VLOOKUP($B8,'Round 3'!$F$2:$H$361,3,false),1)="b","W",if(LEFT(VLOOKUP($B8,'Round 3'!$F$2:$H$361,3,false),1)="a","L",""))) -> W | G8: =iferror(if(LEFT(VLOOKUP($B8,'Round 4'!$B$2:$H$361,7,false),1)="A","W",if(LEFT(VLOOKUP($B8,'Round 4'!$B$2:$H$361,7,false),1)="B","L","")),if(LEFT(VLOOKUP($B8,'Round 4'!$F$2:$H$361,3,false),1)="b","W",if(LEFT(VLOOKUP($B8,'Round 4'!$F$2:$H$361,3,false),1)="a","L",""))) -> W | H8: =iferror(if(LEFT(VLOOKUP($B8,'Round 5'!$B$2:$H$361,7,false),1)="A","W",if(LEFT(VLOOKUP($B8,'Round 5'!$B$2:$H$361,7,false),1)="B","L","")),if(LEFT(VLOOKUP($B8,'Round 5'!$F$2:$H$361,3,false),1)="b","W",if(LEFT(VLOOKUP($B8,'Round 5'!$F$2:$H$361,3,false),1)="a","L",""))) -> W | I8: =iferror(if(LEFT(VLOOKUP($B8,'Round 6'!$B$2:$H$361,7,false),1)="A","W",if(LEFT(VLOOKUP($B8,'Round 6'!$B$2:$H$361,7,false),1)="B","L","")),if(LEFT(VLOOKUP($B8,'Round 6'!$F$2:$H$361,3,false),1)="b","W",if(LEFT(VLOOKUP($B8,'Round 6'!$F$2:$H$361,3,false),1)="a","L",""))) -> W | J8: =iferror(iferror(if(LEFT(VLOOKUP($B8,'Round 7'!$B$2:$H$361,7,false),1)="A","W",if(LEFT(VLOOKUP($B8,'Round 7'!$B$2:$H$361,7,false),1)="B","L","")),if(LEFT(VLOOKUP($B8,'Round 7'!$F$2:$H$361,3,false),1)="b","W",if(LEFT(VLOOKUP($B8,'Round 7'!$F$2:$H$361,3,false),1)="a","L",""))),"") -> W | K8: =iferror(iferror(if(LEFT(VLOOKUP($B8,'Round 8'!$B$2:$H$361,7,false),1)="A","W",if(LEFT(VLOOKUP($B8,'Round 8'!$B$2:$H$361,7,false),1)="B","L","")),if(LEFT(VLOOKUP($B8,'Round 8'!$F$2:$H$361,3,false),1)="b","W",if(LEFT(VLOOKUP($B8,'Round 8'!$F$2:$H$361,3,false),1)="a","L",""))),"") -> W | L8: =iferror(iferror(if(LEFT(VLOOKUP($B8,'Round 9'!$B$2:$H$361,7,false),1)="A","W",if(LEFT(VLOOKUP($B8,'Round 9'!$B$2:$H$361,7,false),1)="B","L","")),if(LEFT(VLOOKUP($B8,'Round 9'!$F$2:$H$361,3,false),1)="b","W",if(LEFT(VLOOKUP($B8,'Round 9'!$F$2:$H$361,3,false),1)="a","L",""))),"") -> W | M8: =iferror(iferror(if(LEFT(VLOOKUP($B8,'Round 10'!$B$2:$H$362,7,false),1)="A","W",if(LEFT(VLOOKUP($B8,'Round 10'!$B$2:$H$362,7,false),1)="B","L","")),if(LEFT(VLOOKUP($B8,'Round 10'!$F$2:$H$362,3,false),1)="b","W",if(LEFT(VLOOKUP($B8,'Round 10'!$F$2:$H$362,3,false),1)="a","L",""))),"") -> W | N8: 127527434865082368
A9: 8 | B9: Leo | C9: =CONCATENATE(COUNTIF(D9:M9,"W") , " - " , COUNTIF(D9:M9, "L")) -> 2 - 3 | D9: =iferror(if(LEFT(VLOOKUP($B9,'Round 1'!$B$2:$H$361,7,false),1)="A","W",if(LEFT(VLOOKUP($B9,'Round 1'!$B$2:$H$361,7,false),1)="B","L","")),if(LEFT(VLOOKUP($B9,'Round 1'!$F$2:$H$361,3,false),1)="b","W",if(LEFT(VLOOKUP($B9,'Round 1'!$F$2:$H$361,3,false),1)="a","L",""))) -> W | E9: =iferror(if(LEFT(VLOOKUP($B9,'Round 2'!$C$2:$J$361,8,false),1)="A","W",if(LEFT(VLOOKUP($B9,'Round 2'!$C$2:$J$361,8,false),1)="B","L","")),if(LEFT(VLOOKUP($B9,'Round 2'!$G$2:$J$361,4,false),1)="b","W",if(LEFT(VLOOKUP($B9,'Round 2'!$G$2:$J$361,4,false),1)="a","L",""))) -> W | F9: =iferror(if(LEFT(VLOOKUP($B9,'Round 3'!$B$2:$H$361,7,false),1)="A","W",if(LEFT(VLOOKUP($B9,'Round 3'!$B$2:$H$361,7,false),1)="B","L","")),if(LEFT(VLOOKUP($B9,'Round 3'!$F$2:$H$361,3,false),1)="b","W",if(LEFT(VLOOKUP($B9,'Round 3'!$F$2:$H$361,3,false),1)="a","L",""))) -> L | G9: =iferror(if(LEFT(VLOOKUP($B9,'Round 4'!$B$2:$H$361,7,false),1)="A","W",if(LEFT(VLOOKUP($B9,'Round 4'!$B$2:$H$361,7,false),1)="B","L","")),if(LEFT(VLOOKUP($B9,'Round 4'!$F$2:$H$361,3,false),1)="b","W",if(LEFT(VLOOKUP($B9,'Round 4'!$F$2:$H$361,3,false),1)="a","L",""))) -> L | H9: =iferror(if(LEFT(VLOOKUP($B9,'Round 5'!$B$2:$H$361,7,false),1)="A","W",if(LEFT(VLOOKUP($B9,'Round 5'!$B$2:$H$361,7,false),1)="B","L","")),if(LEFT(VLOOKUP($B9,'Round 5'!$F$2:$H$361,3,false),1)="b","W",if(LEFT(VLOOKUP($B9,'Round 5'!$F$2:$H$361,3,false),1)="a","L",""))) -> L | J9: =iferror(iferror(if(LEFT(VLOOKUP($B9,'Round 7'!$B$2:$H$361,7,false),1)="A","W",if(LEFT(VLOOKUP($B9,'Round 7'!$B$2:$H$361,7,false),1)="B","L","")),if(LEFT(VLOOKUP($B9,'Round 7'!$F$2:$H$361,3,false),1)="b","W",if(LEFT(VLOOKUP($B9,'Round 7'!$F$2:$H$361,3,false),1)="a","L",""))),"") | K9: =iferror(iferror(if(LEFT(VLOOKUP($B9,'Round 8'!$B$2:$H$361,7,false),1)="A","W",if(LEFT(VLOOKUP($B9,'Round 8'!$B$2:$H$361,7,false),1)="B","L","")),if(LEFT(VLOOKUP($B9,'Round 8'!$F$2:$H$361,3,false),1)="b","W",if(LEFT(VLOOKUP($B9,'Round 8'!$F$2:$H$361,3,false),1)="a","L",""))),"") | L9: =iferror(iferror(if(LEFT(VLOOKUP($B9,'Round 9'!$B$2:$H$361,7,false),1)="A","W",if(LEFT(VLOOKUP($B9,'Round 9'!$B$2:$H$361,7,false),1)="B","L","")),if(LEFT(VLOOKUP($B9,'Round 9'!$F$2:$H$361,3,false),1)="b","W",if(LEFT(VLOOKUP($B9,'Round 9'!$F$2:$H$361,3,false),1)="a","L",""))),"") | M9: =iferror(iferror(if(LEFT(VLOOKUP($B9,'Round 10'!$B$2:$H$362,7,false),1)="A","W",if(LEFT(VLOOKUP($B9,'Round 10'!$B$2:$H$362,7,false),1)="B","L","")),if(LEFT(VLOOKUP($B9,'Round 10'!$F$2:$H$362,3,false),1)="b","W",if(LEFT(VLOOKUP($B9,'Round 10'!$F$2:$H$362,3,false),1)="a","L",""))),"") | N9: 221637804185223170
A10: 9 | B10: Kollin | C10: =CONCATENATE(COUNTIF(D10:M10,"W") , " - " , COUNTIF(D10:M10, "L")) -> 8 - 1 | D10: =iferror(if(LEFT(VLOOKUP($B10,'Round 1'!$B$2:$H$361,7,false),1)="A","W",if(LEFT(VLOOKUP($B10,'Round 1'!$B$2:$H$361,7,false),1)="B","L","")),if(LEFT(VLOOKUP($B10,'Round 1'!$F$2:$H$361,3,false),1)="b","W",if(LEFT(VLOOKUP($B10,'Round 1'!$F$2:$H$361,3,false),1)="a","L",""))) -> W | E10: =iferror(if(LEFT(VLOOKUP($B10,'Round 2'!$C$2:$J$361,8,false),1)="A","W",if(LEFT(VLOOKUP($B10,'Round 2'!$C$2:$J$361,8,false),1)="B","L","")),if(LEFT(VLOOKUP($B10,'Round 2'!$G$2:$J$361,4,false),1)="b","W",if(LEFT(VLOOKUP($B10,'Round 2'!$G$2:$J$361,4,false),1)="a","L",""))) -> W | F10: =iferror(if(LEFT(VLOOKUP($B10,'Round 3'!$B$2:$H$361,7,false),1)="A","W",if(LEFT(VLOOKUP($B10,'Round 3'!$B$2:$H$361,7,false),1)="B","L","")),if(LEFT(VLOOKUP($B10,'Round 3'!$F$2:$H$361,3,false),1)="b","W",if(LEFT(VLOOKUP($B10,'Round 3'!$F$2:$H$361,3,false),1)="a","L",""))) -> W | G10: =iferror(if(LEFT(VLOOKUP($B10,'Round 4'!$B$2:$H$361,7,false),1)="A","W",if(LEFT(VLOOKUP($B10,'Round 4'!$B$2:$H$361,7,false),1)="B","L","")),if(LEFT(VLOOKUP($B10,'Round 4'!$F$2:$H$361,3,false),1)="b","W",if(LEFT(VLOOKUP($B10,'Round 4'!$F$2:$H$361,3,false),1)="a","L",""))) -> W | H10: =iferror(if(LEFT(VLOOKUP($B10,'Round 5'!$B$2:$H$361,7,false),1)="A","W",if(LEFT(VLOOKUP($B10,'Round 5'!$B$2:$H$361,7,false),1)="B","L","")),if(LEFT(VLOOKUP($B10,'Round 5'!$F$2:$H$361,3,false),1)="b","W",if(LEFT(VLOOKUP($B10,'Round 5'!$F$2:$H$361,3,false),1)="a","L",""))) -> W | I10: =iferror(if(LEFT(VLOOKUP($B10,'Round 6'!$B$2:$H$361,7,false),1)="A","W",if(LEFT(VLOOKUP($B10,'Round 6'!$B$2:$H$361,7,false),1)="B","L","")),if(LEFT(VLOOKUP($B10,'Round 6'!$F$2:$H$361,3,false),1)="b","W",if(LEFT(VLOOKUP($B10,'Round 6'!$F$2:$H$361,3,false),1)="a","L",""))) -> W | J10: =iferror(iferror(if(LEFT(VLOOKUP($B10,'Round 7'!$B$2:$H$361,7,false),1)="A","W",if(LEFT(VLOOKUP($B10,'Round 7'!$B$2:$H$361,7,false),1)="B","L","")),if(LEFT(VLOOKUP($B10,'Round 7'!$F$2:$H$361,3,false),1)="b","W",if(LEFT(VLOOKUP($B10,'Round 7'!$F$2:$H$361,3,false),1)="a","L",""))),"") -> W | K10: =iferror(iferror(if(LEFT(VLOOKUP($B10,'Round 8'!$B$2:$H$361,7,false),1)="A","W",if(LEFT(VLOOKUP($B10,'Round 8'!$B$2:$H$361,7,false),1)="B","L","")),if(LEFT(VLOOKUP($B10,'Round 8'!$F$2:$H$361,3,false),1)="b","W",if(LEFT(VLOOKUP($B10,'Round 8'!$F$2:$H$361,3,false),1)="a","L",""))),"") -> W | L10: =iferror(iferror(if(LEFT(VLOOKUP($B10,'Round 9'!$B$2:$H$361,7,false),1)="A","W",if(LEFT(VLOOKUP($B10,'Round 9'!$B$2:$H$361,7,false),1)="B","L","")),if(LEFT(VLOOKUP($B10,'Round 9'!$F$2:$H$361,3,false),1)="b","W",if(LEFT(VLOOKUP($B10,'Round 9'!$F$2:$H$361,3,false),1)="a","L",""))),"") -> L | M10: =iferror(iferror(if(LEFT(VLOOKUP($B10,'Round 10'!$B$2:$H$362,7,false),1)="A","W",if(LEFT(VLOOKUP($B10,'Round 10'!$B$2:$H$362,7,false),1)="B","L","")),if(LEFT(VLOOKUP($B10,'Round 10'!$F$2:$H$362,3,false),1)="b","W",if(LEFT(VLOOKUP($B10,'Round 10'!$F$2:$H$362,3,false),1)="a","L",""))),"") | N10: 83000775151714304
A11: 10 | B11: Cyberodin | C11: =CONCATENATE(COUNTIF(D11:M11,"W") , " - " , COUNTIF(D11:M11, "L")) -> 7 - 2 | D11: =iferror(if(LEFT(VLOOKUP($B11,'Round 1'!$B$2:$H$361,7,false),1)="A","W",if(LEFT(VLOOKUP($B11,'Round 1'!$B$2:$H$361,7,false),1)="B","L","")),if(LEFT(VLOOKUP($B11,'Round 1'!$F$2:$H$361,3,false),1)="b","W",if(LEFT(VLOOKUP($B11,'Round 1'!$F$2:$H$361,3,false),1)="a","L",""))) -> L | E11: =iferror(if(LEFT(VLOOKUP($B11,'Round 2'!$C$2:$J$361,8,false),1)="A","W",if(LEFT(VLOOKUP($B11,'Round 2'!$C$2:$J$361,8,false),1)="B","L","")),if(LEFT(VLOOKUP($B11,'Round 2'!$G$2:$J$361,4,false),1)="b","W",if(LEFT(VLOOKUP($B11,'Round 2'!$G$2:$J$361,4,false),1)="a","L",""))) -> W | F11: =iferror(if(LEFT(VLOOKUP($B11,'Round 3'!$B$2:$H$361,7,false),1)="A","W",if(LEFT(VLOOKUP($B11,'Round 3'!$B$2:$H$361,7,false),1)="B","L","")),if(LEFT(VLOOKUP($B11,'Round 3'!$F$2:$H$361,3,false),1)="b","W",if(LEFT(VLOOKUP($B11,'Round 3'!$F$2:$H$361,3,false),1)="a","L",""))) -> W | G11: =iferror(if(LEFT(VLOOKUP($B11,'Round 4'!$B$2:$H$361,7,false),1)="A","W",if(LEFT(VLOOKUP($B11,'Round 4'!$B$2:$H$361,7,false),1)="B","L","")),if(LEFT(VLOOKUP($B11,'Round 4'!$F$2:$H$361,3,false),1)="b","W",if(LEFT(VLOOKUP($B11,'Round 4'!$F$2:$H$361,3,false),1)="a","L",""))) -> W | H11: =iferror(if(LEFT(VLOOKUP($B11,'Round 5'!$B$2:$H$361,7,false),1)="A","W",if(LEFT(VLOOKUP($B11,'Round 5'!$B$2:$H$361,7,false),1)="B","L","")),if(LEFT(VLOOKUP($B11,'Round 5'!$F$2:$H$361,3,false),1)="b","W",if(LEFT(VLOOKUP($B11,'Round 5'!$F$2:$H$361,3,false),1)="a","L",""))) -> W | I11: =iferror(if(LEFT(VLOOKUP($B11,'Round 6'!$B$2:$H$361,7,false),1)="A","W",if(LEFT(VLOOKUP($B11,'Round 6'!$B$2:$H$361,7,false),1)="B","L","")),if(LEFT(VLOOKUP($B11,'Round 6'!$F$2:$H$361,3,false),1)="b","W",if(LEFT(VLOOKUP($B11,'Round 6'!$F$2:$H$361,3,false),1)="a","L",""))) -> W | J11: =iferror(iferror(if(LEFT(VLOOKUP($B11,'Round 7'!$B$2:$H$361,7,false),1)="A","W",if(LEFT(VLOOKUP($B11,'Round 7'!$B$2:$H$361,7,false),1)="B","L","")),if(LEFT(VLOOKUP($B11,'Round 7'!$F$2:$H$361,3,false),1)="b","W",if(LEFT(VLOOKUP($B11,'Round 7'!$F$2:$H$361,3,false),1)="a","L",""))),"") -> L | K11: =iferror(iferror(if(LEFT(VLOOKUP($B11,'Round 8'!$B$2:$H$361,7,false),1)="A","W",if(LEFT(VLOOKUP($B11,'Round 8'!$B$2:$H$361,7,false),1)="B","L","")),if(LEFT(VLOOKUP($B11,'Round 8'!$F$2:$H$361,3,false),1)="b","W",if(LEFT(VLOOKUP($B11,'Round 8'!$F$2:$H$361,3,false),1)="a","L",""))),"") -> W | L11: =iferror(iferror(if(LEFT(VLOOKUP($B11,'Round 9'!$B$2:$H$361,7,false),1)="A","W",if(LEFT(VLOOKUP($B11,'Round 9'!$B$2:$H$361,7,false),1)="B","L","")),if(LEFT(VLOOKUP($B11,'Round 9'!$F$2:$H$361,3,false),1)="b","W",if(LEFT(VLOOKUP($B11,'Round 9'!$F$2:$H$361,3,false),1)="a","L",""))),"") -> W | M11: =iferror(iferror(if(LEFT(VLOOKUP($B11,'Round 10'!$B$2:$H$362,7,false),1)="A","W",if(LEFT(VLOOKUP($B11,'Round 10'!$B$2:$H$362,7,false),1)="B","L","")),if(LEFT(VLOOKUP($B11,'Round 10'!$F$2:$H$362,3,false),1)="b","W",if(LEFT(VLOOKUP($B11,'Round 10'!$F$2:$H$362,3,false),1)="a","L",""))),"") | N11: 259426043285340160
A12: 11 | B12: Blues | C12: =CONCATENATE(COUNTIF(D12:M12,"W") , " - " , COUNTIF(D12:M12, "L")) -> 6 - 3 | D12: =iferror(if(LEFT(VLOOKUP($B12,'Round 1'!$B$2:$H$361,7,false),1)="A","W",if(LEFT(VLOOKUP($B12,'Round 1'!$B$2:$H$361,7,false),1)="B","L","")),if(LEFT(VLOOKUP($B12,'Round 1'!$F$2:$H$361,3,false),1)="b","W",if(LEFT(VLOOKUP($B12,'Round 1'!$F$2:$H$361,3,false),1)="a","L",""))) -> W | E12: =iferror(if(LEFT(VLOOKUP($B12,'Round 2'!$C$2:$J$361,8,false),1)="A","W",if(LEFT(VLOOKUP($B12,'Round 2'!$C$2:$J$361,8,false),1)="B","L","")),if(LEFT(VLOOKUP($B12,'Round 2'!$G$2:$J$361,4,false),1)="b","W",if(LEFT(VLOOKUP($B12,'Round 2'!$G$2:$J$361,4,false),1)="a","L",""))) -> W | F12: =iferror(if(LEFT(VLOOKUP($B12,'Round 3'!$B$2:$H$361,7,false),1)="A","W",if(LEFT(VLOOKUP($B12,'Round 3'!$B$2:$H$361,7,false),1)="B","L","")),if(LEFT(VLOOKUP($B12,'Round 3'!$F$2:$H$361,3,false),1)="b","W",if(LEFT(VLOOKUP($B12,'Round 3'!$F$2:$H$361,3,false),1)="a","L",""))) -> L | G12: =iferror(if(LEFT(VLOOKUP($B12,'Round 4'!$B$2:$H$361,7,false),1)="A","W",if(LEFT(VLOOKUP($B12,'Round 4'!$B$2:$H$361,7,false),1)="B","L","")),if(LEFT(VLOOKUP($B12,'Round 4'!$F$2:$H$361,3,false),1)="b","W",if(LEFT(VLOOKUP($B12,'Round 4'!$F$2:$H$361,3,false),1)="a","L",""))) -> W | H12: =iferror(if(LEFT(VLOOKUP($B12,'Round 5'!$B$2:$H$361,7,false),1)="A","W",if(LEFT(VLOOKUP($B12,'Round 5'!$B$2:$H$361,7,false),1)="B","L","")),if(LEFT(VLOOKUP($B12,'Round 5'!$F$2:$H$361,3,false),1)="b","W",if(LEFT(VLOOKUP($B12,'Round 5'!$F$2:$H$361,3,false),1)="a","L",""))) -> W | I12: =iferror(if(LEFT(VLOOKUP($B12,'Round 6'!$B$2:$H$361,7,false),1)="A","W",if(LEFT(VLOOKUP($B12,'Round 6'!$B$2:$H$361,7,false),1)="B","L","")),if(LEFT(VLOOKUP($B12,'Round 6'!$F$2:$H$361,3,false),1)="b","W",if(LEFT(VLOOKUP($B12,'Round 6'!$F$2:$H$361,3,false),1)="a","L",""))) -> W | J12: =iferror(iferror(if(LEFT(VLOOKUP($B12,'Round 7'!$B$2:$H$361,7,false),1)="A","W",if(LEFT(VLOOKUP($B12,'Round 7'!$B$2:$H$361,7,false),1)="B","L","")),if(LEFT(VLOOKUP($B12,'Round 7'!$F$2:$H$361,3,false),1)="b","W",if(LEFT(VLOOKUP($B12,'Round 7'!$F$2:$H$361,3,false),1)="a","L",""))),"") -> W | K12: =iferror(iferror(if(LEFT(VLOOKUP($B12,'Round 8'!$B$2:$H$361,7,false),1)="A","W",if(LEFT(VLOOKUP($B12,'Round 8'!$B$2:$H$361,7,false),1)="B","L","")),if(LEFT(VLOOKUP($B12,'Round 8'!$F$2:$H$361,3,false),1)="b","W",if(LEFT(VLOOKUP($B12,'Round 8'!$F$2:$H$361,3,false),1)="a","L",""))),"") -> L | L12: =iferror(iferror(if(LEFT(VLOOKUP($B12,'Round 9'!$B$2:$H$361,7,false),1)="A","W",if(LEFT(VLOOKUP($B12,'Round 9'!$B$2:$H$361,7,false),1)="B","L","")),if(LEFT(VLOOKUP($B12,'Round 9'!$F$2:$H$361,3,false),1)="b","W",if(LEFT(VLOOKUP($B12,'Round 9'!$F$2:$H$361,3,false),1)="a","L",""))),"") -> L | M12: =iferror(iferror(if(LEFT(VLOOKUP($B12,'Round 10'!$B$2:$H$362,7,false),1)="A","W",if(LEFT(VLOOKUP($B12,'Round 10'!$B$2:$H$362,7,false),1)="B","L","")),if(LEFT(VLOOKUP($B12,'Round 10'!$F$2:$H$362,3,false),1)="b","W",if(LEFT(VLOOKUP($B12,'Round 10'!$F$2:$H$362,3,false),1)="a","L",""))),"") | N12: 687987394292482066
A13: 12 | B13: Pak | C13: =CONCATENATE(COUNTIF(D13:M13,"W") , " - " , COUNTIF(D13:M13, "L")) -> 8 - 1 | D13: =iferror(if(LEFT(VLOOKUP($B13,'Round 1'!$B$2:$H$361,7,false),1)="A","W",if(LEFT(VLOOKUP($B13,'Round 1'!$B$2:$H$361,7,false),1)="B","L","")),if(LEFT(VLOOKUP($B13,'Round 1'!$F$2:$H$361,3,false),1)="b","W",if(LEFT(VLOOKUP($B13,'Round 1'!$F$2:$H$361,3,false),1)="a","L",""))) -> W | E13: =iferror(if(LEFT(VLOOKUP($B13,'Round 2'!$C$2:$J$361,8,false),1)="A","W",if(LEFT(VLOOKUP($B13,'Round 2'!$C$2:$J$361,8,false),1)="B","L","")),if(LEFT(VLOOKUP($B13,'Round 2'!$G$2:$J$361,4,false),1)="b","W",if(LEFT(VLOOKUP($B13,'Round 2'!$G$2:$J$361,4,false),1)="a","L",""))) -> L | F13: =iferror(if(LEFT(VLOOKUP($B13,'Round 3'!$B$2:$H$361,7,false),1)="A","W",if(LEFT(VLOOKUP($B13,'Round 3'!$B$2:$H$361,7,false),1)="B","L","")),if(LEFT(VLOOKUP($B13,'Round 3'!$F$2:$H$361,3,false),1)="b","W",if(LEFT(VLOOKUP($B13,'Round 3'!$F$2:$H$361,3,false),1)="a","L",""))) -> W | G13: =iferror(if(LEFT(VLOOKUP($B13,'Round 4'!$B$2:$H$361,7,false),1)="A","W",if(LEFT(VLOOKUP($B13,'Round 4'!$B$2:$H$361,7,false),1)="B","L","")),if(LEFT(VLOOKUP($B13,'Round 4'!$F$2:$H$361,3,false),1)="b","W",if(LEFT(VLOOKUP($B13,'Round 4'!$F$2:$H$361,3,false),1)="a","L",""))) -> W | H13: =iferror(if(LEFT(VLOOKUP($B13,'Round 5'!$B$2:$H$361,7,false),1)="A","W",if(LEFT(VLOOKUP($B13,'Round 5'!$B$2:$H$361,7,false),1)="B","L","")),if(LEFT(VLOOKUP($B13,'Round 5'!$F$2:$H$361,3,false),1)="b","W",if(LEFT(VLOOKUP($B13,'Round 5'!$F$2:$H$361,3,false),1)="a","L",""))) -> W | I13: =iferror(if(LEFT(VLOOKUP($B13,'Round 6'!$B$2:$H$361,7,false),1)="A","W",if(LEFT(VLOOKUP($B13,'Round 6'!$B$2:$H$361,7,false),1)="B","L","")),if(LEFT(VLOOKUP($B13,'Round 6'!$F$2:$H$361,3,false),1)="b","W",if(LEFT(VLOOKUP($B13,'Round 6'!$F$2:$H$361,3,false),1)="a","L",""))) -> W | J13: =iferror(iferror(if(LEFT(VLOOKUP($B13,'Round 7'!$B$2:$H$361,7,false),1)="A","W",if(LEFT(VLOOKUP($B13,'Round 7'!$B$2:$H$361,7,false),1)="B","L","")),if(LEFT(VLOOKUP($B13,'Round 7'!$F$2:$H$361,3,false),1)="b","W",if(LEFT(VLOOKUP($B13,'Round 7'!$F$2:$H$361,3,false),1)="a","L",""))),"") -> W | K13: =iferror(iferror(if(LEFT(VLOOKUP($B13,'Round 8'!$B$2:$H$361,7,false),1)="A","W",if(LEFT(VLOOKUP($B13,'Round 8'!$B$2:$H$361,7,false),1)="B","L","")),if(LEFT(VLOOKUP($B13,'Round 8'!$F$2:$H$361,3,false),1)="b","W",if(LEFT(VLOOKUP($B13,'Round 8'!$F$2:$H$361,3,false),1)="a","L",""))),"") -> W | L13: =iferror(iferror(if(LEFT(VLOOKUP($B13,'Round 9'!$B$2:$H$361,7,false),1)="A","W",if(LEFT(VLOOKUP($B13,'Round 9'!$B$2:$H$361,7,false),1)="B","L","")),if(LEFT(VLOOKUP($B13,'Round 9'!$F$2:$H$361,3,false),1)="b","W",if(LEFT(VLOOKUP($B13,'Round 9'!$F$2:$H$361,3,false),1)="a","L",""))),"") -> W | M13: =iferror(iferror(if(LEFT(VLOOKUP($B13,'Round 10'!$B$2:$H$362,7,false),1)="A","W",if(LEFT(VLOOKUP($B13,'Round 10'!$B$2:$H$362,7,false),1)="B","L","")),if(LEFT(VLOOKUP($B13,'Round 10'!$F$2:$H$362,3,false),1)="b","W",if(LEFT(VLOOKUP($B13,'Round 10'!$F$2:$H$362,3,false),1)="a","L",""))),"") | N13: 172884622986706945
A14: 13 | B14: River | C14: =CONCATENATE(COUNTIF(D14:M14,"W") , " - " , COUNTIF(D14:M14, "L")) -> 6 - 3 | D14: =iferror(if(LEFT(VLOOKUP($B14,'Round 1'!$B$2:$H$361,7,false),1)="A","W",if(LEFT(VLOOKUP($B14,'Round 1'!$B$2:$H$361,7,false),1)="B","L","")),if(LEFT(VLOOKUP($B14,'Round 1'!$F$2:$H$361,3,false),1)="b","W",if(LEFT(VLOOKUP($B14,'Round 1'!$F$2:$H$361,3,false),1)="a","L",""))) -> W | E14: =iferror(if(LEFT(VLOOKUP($B14,'Round 2'!$C$2:$J$361,8,false),1)="A","W",if(LEFT(VLOOKUP($B14,'Round 2'!$C$2:$J$361,8,false),1)="B","L","")),if(LEFT(VLOOKUP($B14,'Round 2'!$G$2:$J$361,4,false),1)="b","W",if(LEFT(VLOOKUP($B14,'Round 2'!$G$2:$J$361,4,false),1)="a","L",""))) -> W | F14: =iferror(if(LEFT(VLOOKUP($B14,'Round 3'!$B$2:$H$361,7,false),1)="A","W",if(LEFT(VLOOKUP($B14,'Round 3'!$B$2:$H$361,7,false),1)="B","L","")),if(LEFT(VLOOKUP($B14,'Round 3'!$F$2:$H$361,3,false),1)="b","W",if(LEFT(VLOOKUP($B14,'Round 3'!$F$2:$H$361,3,false),1)="a","L",""))) -> W | G14: =iferror(if(LEFT(VLOOKUP($B14,'Round 4'!$B$2:$H$361,7,false),1)="A","W",if(LEFT(VLOOKUP($B14,'Round 4'!$B$2:$H$361,7,false),1)="B","L","")),if(LEFT(VLOOKUP($B14,'Round 4'!$F$2:$H$361,3,false),1)="b","W",if(LEFT(VLOOKUP($B14,'Round 4'!$F$2:$H$361,3,false),1)="a","L",""))) -> W | H14: =iferror(if(LEFT(VLOOKUP($B14,'Round 5'!$B$2:$H$361,7,false),1)="A","W",if(LEFT(VLOOKUP($B14,'Round 5'!$B$2:$H$361,7,false),1)="B","L","")),if(LEFT(VLOOKUP($B14,'Round 5'!$F$2:$H$361,3,false),1)="b","W",if(LEFT(VLOOKUP($B14,'Round 5'!$F$2:$H$361,3,false),1)="a","L",""))) -> L | I14: =iferror(if(LEFT(VLOOKUP($B14,'Round 6'!$B$2:$H$361,7,false),1)="A","W",if(LEFT(VLOOKUP($B14,'Round 6'!$B$2:$H$361,7,false),1)="B","L","")),if(LEFT(VLOOKUP($B14,'Round 6'!$F$2:$H$361,3,false),1)="b","W",if(LEFT(VLOOKUP($B14,'Round 6'!$F$2:$H$361,3,false),1)="a","L",""))) -> W | J14: =iferror(iferror(if(LEFT(VLOOKUP($B14,'Round 7'!$B$2:$H$361,7,false),1)="A","W",if(LEFT(VLOOKUP($B14,'Round 7'!$B$2:$H$361,7,false),1)="B","L","")),if(LEFT(VLOOKUP($B14,'Round 7'!$F$2:$H$361,3,false),1)="b","W",if(LEFT(VLOOKUP($B14,'Round 7'!$F$2:$H$361,3,false),1)="a","L",""))),"") -> W | K14: =iferror(iferror(if(LEFT(VLOOKUP($B14,'Round 8'!$B$2:$H$361,7,false),1)="A","W",if(LEFT(VLOOKUP($B14,'Round 8'!$B$2:$H$361,7,false),1)="B","L","")),if(LEFT(VLOOKUP($B14,'Round 8'!$F$2:$H$361,3,false),1)="b","W",if(LEFT(VLOOKUP($B14,'Round 8'!$F$2:$H$361,3,false),1)="a","L",""))),"") -> L | L14: =iferror(iferror(if(LEFT(VLOOKUP($B14,'Round 9'!$B$2:$H$361,7,false),1)="A","W",if(LEFT(VLOOKUP($B14,'Round 9'!$B$2:$H$361,7,false),1)="B","L","")),if(LEFT(VLOOKUP($B14,'Round 9'!$F$2:$H$361,3,false),1)="b","W",if(LEFT(VLOOKUP($B14,'Round 9'!$F$2:$H$361,3,false),1)="a","L",""))),"") -> L | M14: =iferror(iferror(if(LEFT(VLOOKUP($B14,'Round 10'!$B$2:$H$362,7,false),1)="A","W",if(LEFT(VLOOKUP($B14,'Round 10'!$B$2:$H$362,7,false),1)="B","L","")),if(LEFT(VLOOKUP($B14,'Round 10'!$F$2:$H$362,3,false),1)="b","W",if(LEFT(VLOOKUP($B14,'Round 10'!$F$2:$H$362,3,false),1)="a","L",""))),"") | N14: 543280883000541224
A15: 14 | B15: Voyager | C15: =CONCATENATE(COUNTIF(D15:M15,"W") , " - " , COUNTIF(D15:M15, "L")) -> 7 - 2 | D15: =iferror(if(LEFT(VLOOKUP($B15,'Round 1'!$B$2:$H$361,7,false),1)="A","W",if(LEFT(VLOOKUP($B15,'Round 1'!$B$2:$H$361,7,false),1)="B","L","")),if(LEFT(VLOOKUP($B15,'Round 1'!$F$2:$H$361,3,false),1)="b","W",if(LEFT(VLOOKUP($B15,'Round 1'!$F$2:$H$361,3,false),1)="a","L",""))) -> W | E15: =iferror(if(LEFT(VLOOKUP($B15,'Round 2'!$C$2:$J$361,8,false),1)="A","W",if(LEFT(VLOOKUP($B15,'Round 2'!$C$2:$J$361,8,false),1)="B","L","")),if(LEFT(VLOOKUP($B15,'Round 2'!$G$2:$J$361,4,false),1)="b","W",if(LEFT(VLOOKUP($B15,'Round 2'!$G$2:$J$361,4,false),1)="a","L",""))) -> W | F15: =iferror(if(LEFT(VLOOKUP($B15,'Round 3'!$B$2:$H$361,7,false),1)="A","W",if(LEFT(VLOOKUP($B15,'Round 3'!$B$2:$H$361,7,false),1)="B","L","")),if(LEFT(VLOOKUP($B15,'Round 3'!$F$2:$H$361,3,false),1)="b","W",if(LEFT(VLOOKUP($B15,'Round 3'!$F$2:$H$361,3,false),1)="a","L",""))) -> W | G15: =iferror(if(LEFT(VLOOKUP($B15,'Round 4'!$B$2:$H$361,7,false),1)="A","W",if(LEFT(VLOOKUP($B15,'Round 4'!$B$2:$H$361,7,false),1)="B","L","")),if(LEFT(VLOOKUP($B15,'Round 4'!$F$2:$H$361,3,false),1)="b","W",if(LEFT(VLOOKUP($B15,'Round 4'!$F$2:$H$361,3,false),1)="a","L",""))) -> L | H15: =iferror(if(LEFT(VLOOKUP($B15,'Round 5'!$B$2:$H$361,7,false),1)="A","W",if(LEFT(VLOOKUP($B15,'Round 5'!$B$2:$H$361,7,false),1)="B","L","")),if(LEFT(VLOOKUP($B15,'Round 5'!$F$2:$H$361,3,false),1)="b","W",if(LEFT(VLOOKUP($B15,'Round 5'!$F$2:$H$361,3,false),1)="a","L",""))) -> L | I15: =iferror(if(LEFT(VLOOKUP($B15,'Round 6'!$B$2:$H$361,7,false),1)="A","W",if(LEFT(VLOOKUP($B15,'Round 6'!$B$2:$H$361,7,false),1)="B","L","")),if(LEFT(VLOOKUP($B15,'Round 6'!$F$2:$H$361,3,false),1)="b","W",if(LEFT(VLOOKUP($B15,'Round 6'!$F$2:$H$361,3,false),1)="a","L",""))) -> W | J15: =iferror(iferror(if(LEFT(VLOOKUP($B15,'Round 7'!$B$2:$H$361,7,false),1)="A","W",if(LEFT(VLOOKUP($B15,'Round 7'!$B$2:$H$361,7,false),1)="B","L","")),if(LEFT(VLOOKUP($B15,'Round 7'!$F$2:$H$361,3,false),1)="b","W",if(LEFT(VLOOKUP($B15,'Round 7'!$F$2:$H$361,3,false),1)="a","L",""))),"") -> W | K15: =iferror(iferror(if(LEFT(VLOOKUP($B15,'Round 8'!$B$2:$H$361,7,false),1)="A","W",if(LEFT(VLOOKUP($B15,'Round 8'!$B$2:$H$361,7,false),1)="B","L","")),if(LEFT(VLOOKUP($B15,'Round 8'!$F$2:$H$361,3,false),1)="b","W",if(LEFT(VLOOKUP($B15,'Round 8'!$F$2:$H$361,3,false),1)="a","L",""))),"") -> W | L15: =iferror(iferror(if(LEFT(VLOOKUP($B15,'Round 9'!$B$2:$H$361,7,false),1)="A","W",if(LEFT(VLOOKUP($B15,'Round 9'!$B$2:$H$361,7,false),1)="B","L","")),if(LEFT(VLOOKUP($B15,'Round 9'!$F$2:$H$361,3,false),1)="b","W",if(LEFT(VLOOKUP($B15,'Round 9'!$F$2:$H$361,3,false),1)="a","L",""))),"") -> W | M15: =iferror(iferror(if(LEFT(VLOOKUP($B15,'Round 10'!$B$2:$H$362,7,false),1)="A","W",if(LEFT(VLOOKUP($B15,'Round 10'!$B$2:$H$362,7,false),1)="B","L","")),if(LEFT(VLOOKUP($B15,'Round 10'!$F$2:$H$362,3,false),1)="b","W",if(LEFT(VLOOKUP($B15,'Round 10'!$F$2:$H$362,3,false),1)="a","L",""))),"") | N15: 554730792488534056
A16: 15 | B16: Carapinga | C16: =CONCATENATE(COUNTIF(D16:M16,"W") , " - " , COUNTIF(D16:M16, "L")) -> 5 - 3 | D16: =iferror(if(LEFT(VLOOKUP($B16,'Round 1'!$B$2:$H$361,7,false),1)="A","W",if(LEFT(VLOOKUP($B16,'Round 1'!$B$2:$H$361,7,false),1)="B","L","")),if(LEFT(VLOOKUP($B16,'Round 1'!$F$2:$H$361,3,false),1)="b","W",if(LEFT(VLOOKUP($B16,'Round 1'!$F$2:$H$361,3,false),1)="a","L",""))) -> W | E16: =iferror(if(LEFT(VLOOKUP($B16,'Round 2'!$C$2:$J$361,8,false),1)="A","W",if(LEFT(VLOOKUP($B16,'Round 2'!$C$2:$J$361,8,false),1)="B","L","")),if(LEFT(VLOOKUP($B16,'Round 2'!$G$2:$J$361,4,false),1)="b","W",if(LEFT(VLOOKUP($B16,'Round 2'!$G$2:$J$361,4,false),1)="a","L",""))) -> W | F16: =iferror(if(LEFT(VLOOKUP($B16,'Round 3'!$B$2:$H$361,7,false),1)="A","W",if(LEFT(VLOOKUP($B16,'Round 3'!$B$2:$H$361,7,false),1)="B","L","")),if(LEFT(VLOOKUP($B16,'Round 3'!$F$2:$H$361,3,false),1)="b","W",if(LEFT(VLOOKUP($B16,'Round 3'!$F$2:$H$361,3,false),1)="a","L",""))) -> W | G16: =iferror(if(LEFT(VLOOKUP($B16,'Round 4'!$B$2:$H$361,7,false),1)="A","W",if(LEFT(VLOOKUP($B16,'Round 4'!$B$2:$H$361,7,false),1)="B","L","")),if(LEFT(VLOOKUP($B16,'Round 4'!$F$2:$H$361,3,false),1)="b","W",if(LEFT(VLOOKUP($B16,'Round 4'!$F$2:$H$361,3,false),1)="a","L",""))) -> W | H16: =iferror(if(LEFT(VLOOKUP($B16,'Round 5'!$B$2:$H$361,7,false),1)="A","W",if(LEFT(VLOOKUP($B16,'Round 5'!$B$2:$H$361,7,false),1)="B","L","")),if(LEFT(VLOOKUP($B16,'Round 5'!$F$2:$H$361,3,false),1)="b","W",if(LEFT(VLOOKUP($B16,'Round 5'!$F$2:$H$361,3,false),1)="a","L",""))) -> L | I16: =iferror(if(LEFT(VLOOKUP($B16,'Round 6'!$B$2:$H$361,7,false),1)="A","W",if(LEFT(VLOOKUP($B16,'Round 6'!$B$2:$H$361,7,false),1)="B","L","")),if(LEFT(VLOOKUP($B16,'Round 6'!$F$2:$H$361,3,false),1)="b","W",if(LEFT(VLOOKUP($B16,'Round 6'!$F$2:$H$361,3,false),1)="a","L",""))) -> W | J16: =iferror(iferror(if(LEFT(VLOOKUP($B16,'Round 7'!$B$2:$H$361,7,false),1)="A","W",if(LEFT(VLOOKUP($B16,'Round 7'!$B$2:$H$361,7,false),1)="B","L","")),if(LEFT(VLOOKUP($B16,'Round 7'!$F$2:$H$361,3,false),1)="b","W",if(LEFT(VLOOKUP($B16,'Round 7'!$F$2:$H$361,3,false),1)="a","L",""))),"") -> L | K16: =iferror(iferror(if(LEFT(VLOOKUP($B16,'Round 8'!$B$2:$H$361,7,false),1)="A","W",if(LEFT(VLOOKUP($B16,'Round 8'!$B$2:$H$361,7,false),1)="B","L","")),if(LEFT(VLOOKUP($B16,'Round 8'!$F$2:$H$361,3,false),1)="b","W",if(LEFT(VLOOKUP($B16,'Round 8'!$F$2:$H$361,3,false),1)="a","L",""))),"") -> L | L16: =iferror(iferror(if(LEFT(VLOOKUP($B16,'Round 9'!$B$2:$H$361,7,false),1)="A","W",if(LEFT(VLOOKUP($B16,'Round 9'!$B$2:$H$361,7,false),1)="B","L","")),if(LEFT(VLOOKUP($B16,'Round 9'!$F$2:$H$361,3,false),1)="b","W",if(LEFT(VLOOKUP($B16,'Round 9'!$F$2:$H$361,3,false),1)="a","L",""))),"") | M16: =iferror(iferror(if(LEFT(VLOOKUP($B16,'Round 10'!$B$2:$H$362,7,false),1)="A","W",if(LEFT(VLOOKUP($B16,'Round 10'!$B$2:$H$362,7,false),1)="B","L","")),if(LEFT(VLOOKUP($B16,'Round 10'!$F$2:$H$362,3,false),1)="b","W",if(LEFT(VLOOKUP($B16,'Round 10'!$F$2:$H$362,3,false),1)="a","L",""))),"") | N16: 475993004994330629
A17: 16 | B17: Mielke | C17: =CONCATENATE(COUNTIF(D17:M17,"W") , " - " , COUNTIF(D17:M17, "L")) -> 8 - 1 | D17: =iferror(if(LEFT(VLOOKUP($B17,'Round 1'!$B$2:$H$361,7,false),1)="A","W",if(LEFT(VLOOKUP($B17,'Round 1'!$B$2:$H$361,7,false),1)="B","L","")),if(LEFT(VLOOKUP($B17,'Round 1'!$F$2:$H$361,3,false),1)="b","W",if(LEFT(VLOOKUP($B17,'Round 1'!$F$2:$H$361,3,false),1)="a","L",""))) -> W | E17: =iferror(if(LEFT(VLOOKUP($B17,'Round 2'!$C$2:$J$361,8,false),1)="A","W",if(LEFT(VLOOKUP($B17,'Round 2'!$C$2:$J$361,8,false),1)="B","L","")),if(LEFT(VLOOKUP($B17,'Round 2'!$G$2:$J$361,4,false),1)="b","W",if(LEFT(VLOOKUP($B17,'Round 2'!$G$2:$J$361,4,false),1)="a","L",""))) -> W | F17: =iferror(if(LEFT(VLOOKUP($B17,'Round 3'!$B$2:$H$361,7,false),1)="A","W",if(LEFT(VLOOKUP($B17,'Round 3'!$B$2:$H$361,7,false),1)="B","L","")),if(LEFT(VLOOKUP($B17,'Round 3'!$F$2:$H$361,3,false),1)="b","W",if(LEFT(VLOOKUP($B17,'Round 3'!$F$2:$H$361,3,false),1)="a","L",""))) -> W | G17: =iferror(if(LEFT(VLOOKUP($B17,'Round 4'!$B$2:$H$361,7,false),1)="A","W",if(LEFT(VLOOKUP($B17,'Round 4'!$B$2:$H$361,7,false),1)="B","L","")),if(LEFT(VLOOKUP($B17,'Round 4'!$F$2:$H$361,3,false),1)="b","W",if(LEFT(VLOOKUP($B17,'Round 4'!$F$2:$H$361,3,false),1)="a","L",""))) -> W | H17: =iferror(if(LEFT(VLOOKUP($B17,'Round 5'!$B$2:$H$361,7,false),1)="A","W",if(LEFT(VLOOKUP($B17,'Round 5'!$B$2:$H$361,7,false),1)="B","L","")),if(LEFT(VLOOKUP($B17,'Round 5'!$F$2:$H$361,3,false),1)="b","W",if(LEFT(VLOOKUP($B17,'Round 5'!$F$2:$H$361,3,false),1)="a","L",""))) -> W | I17: =iferror(if(LEFT(VLOOKUP($B17,'Round 6'!$B$2:$H$361,7,false),1)="A","W",if(LEFT(VLOOKUP($B17,'Round 6'!$B$2:$H$361,7,false),1)="B","L","")),if(LEFT(VLOOKUP($B17,'Round 6'!$F$2:$H$361,3,false),1)="b","W",if(LEFT(VLOOKUP($B17,'Round 6'!$F$2:$H$361,3,false),1)="a","L",""))) -> W | J17: =iferror(iferror(if(LEFT(VLOOKUP($B17,'Round 7'!$B$2:$H$361,7,false),1)="A","W",if(LEFT(VLOOKUP($B17,'Round 7'!$B$2:$H$361,7,false),1)="B","L","")),if(LEFT(VLOOKUP($B17,'Round 7'!$F$2:$H$361,3,false),1)="b","W",if(LEFT(VLOOKUP($B17,'Round 7'!$F$2:$H$361,3,false),1)="a","L",""))),"") -> W | K17: =iferror(iferror(if(LEFT(VLOOKUP($B17,'Round 8'!$B$2:$H$361,7,false),1)="A","W",if(LEFT(VLOOKUP($B17,'Round 8'!$B$2:$H$361,7,false),1)="B","L","")),if(LEFT(VLOOKUP($B17,'Round 8'!$F$2:$H$361,3,false),1)="b","W",if(LEFT(VLOOKUP($B17,'Round 8'!$F$2:$H$361,3,false),1)="a","L",""))),"") -> L | L17: =iferror(iferror(if(LEFT(VLOOKUP($B17,'Round 9'!$B$2:$H$361,7,false),1)="A","W",if(LEFT(VLOOKUP($B17,'Round 9'!$B$2:$H$361,7,false),1)="B","L","")),if(LEFT(VLOOKUP($B17,'Round 9'!$F$2:$H$361,3,false),1)="b","W",if(LEFT(VLOOKUP($B17,'Round 9'!$F$2:$H$361,3,false),1)="a","L",""))),"") -> W | M17: =iferror(iferror(if(LEFT(VLOOKUP($B17,'Round 10'!$B$2:$H$362,7,false),1)="A","W",if(LEFT(VLOOKUP($B17,'Round 10'!$B$2:$H$362,7,false),1)="B","L","")),if(LEFT(VLOOKUP($B17,'Round 10'!$F$2:$H$362,3,false),1)="b","W",if(LEFT(VLOOKUP($B17,'Round 10'!$F$2:$H$362,3,false),1)="a","L",""))),"") | N17: 324650949371232257
